Workbook
Name Names: Model!#REF!

Sheet Model
F2: 0.8 | G2: =_xll.PTreeNodeProbability(treeCalc_1!$F$2,9) -> 0
F3: 10000 | G3: =_xll.PTreeNodeValue(treeCalc_1!$F$2,9) -> 2500
E4: 0.8 | F4: Underbid Competitor
E5: 0 | F5: =_xll.PTreeNodeValue(treeCalc_1!$F$2,7) -> 500
F6: 0.2 | G6: =_xll.PTreeNodeProbability(treeCalc_1!$F$2,10) -> 0
F7: 0 | G7: =_xll.PTreeNodeValue(treeCalc_1!$F$2,10) -> -7500
D8: =_xll.PTreeNodeDecision(treeCalc_1!$F$2,4) -> FALSE | E8: Any competing bid
D9: 0 | E9: =_xll.PTreeNodeValue(treeCalc_1!$F$2,4) -> 900
E10: 0.2 | F10: =_xll.PTreeNodeProbability(treeCalc_1!$F$2,8) -> 0
E11: 10000 | F11: =_xll.PTreeNodeValue(treeCalc_1!$F$2,8) -> 2500
C12: =_xll.PTreeNodeDecision(treeCalc_1!$F$2,2) -> TRUE | D12: Bid Amount
C13: -7500 | D13: =_xll.PTreeNodeValue(treeCalc_1!$F$2,2) -> 2900
F14: 0.4 | G14: =_xll.PTreeNodeProbability(treeCalc_1!$F$2,11) -> 0.32
F15: 20000 | G15: =_xll.PTreeNodeValue(treeCalc_1!$F$2,11) -> 12500
E16: 0.8 | F16: Underbid Competitor
E17: 0 | F17: =_xll.PTreeNodeValue(treeCalc_1!$F$2,13) -> 500
F18: 0.6 | G18: =_xll.PTreeNodeProbability(treeCalc_1!$F$2,12) -> 0.48
F19: 0 | G19: =_xll.PTreeNodeValue(treeCalc_1!$F$2,12) -> -7500
D20: =_xll.PTreeNodeDecision(treeCalc_1!$F$2,5) -> TRUE | E20: Any competing bid
D21: 0 | E21: =_xll.PTreeNodeValue(treeCalc_1!$F$2,5) -> 2900
E22: 0.2 | F22: =_xll.PTreeNodeProbability(treeCalc_1!$F$2,18) -> 0.2
E23: 20000 | F23: =_xll.PTreeNodeValue(treeCalc_1!$F$2,18) -> 12500
F24: 0.1 | G24: =_xll.PTreeNodeProbability(treeCalc_1!$F$2,14) -> 0
F25: 30000 | G25: =_xll.PTreeNodeValue(treeCalc_1!$F$2,14) -> 22500
E26: 0.8 | F26: Underbid Competitor
E27: 0 | F27: =_xll.PTreeNodeValue(treeCalc_1!$F$2,19) -> -4500
F28: 0.9 | G28: =_xll.PTreeNodeProbability(treeCalc_1!$F$2,15) -> 0
F29: 0 | G29: =_xll.PTreeNodeValue(treeCalc_1!$F$2,15) -> -7500
D30: =_xll.PTreeNodeDecision(treeCalc_1!$F$2,6) -> FALSE | E30: Any competing bid
D31: 0 | E31: =_xll.PTreeNodeValue(treeCalc_1!$F$2,6) -> 900
E32: 0.2 | F32: =_xll.PTreeNodeProbability(treeCalc_1!$F$2,24) -> 0
E33: 30000 | F33: =_xll.PTreeNodeValue(treeCalc_1!$F$2,24) -> 22500
C34: Place a bid
C35: =_xll.PTreeNodeValue(treeCalc_1!$F$2,1) -> 2900
C36: =_xll.PTreeNodeDecision(treeCalc_1!$F$2,3) -> FALSE | D36: =_xll.PTreeNodeProbability(treeCalc_1!$F$2,3) -> 0
C37: 0 | D37: =_xll.PTreeNodeValue(treeCalc_1!$F$2,3) -> 0

Sheet treeCalc_1
A1: Name | B1: Bidding Decision | E1: Ptree1 Compatibility | F1: 3 | H1: Output Label | K1: R-Value Ref. | L1: 100
A2: SheetRef | B2: =Model!#REF! -> #REF! | E2: Eval. Function | F2: =_xll.PTreeEvaluate5(B3,$L$11:$L$34,$J$11:$J$34,$K$11:$K$34,$N$11:$N$34,$G$11:$G$34,,L1) -> 154369
A3: GenInfo | B3: 0,1,1,0,0,Exponential, 0,0,-1,0,-1,-1,.0001 | E3: Creation Version | F3: 6.0.0 | H3: Output Value NF | I3: <NF>
A4: Def. Link | B4: = | E4: Required Version | F4: 5.0.0 | H4: Output Prob NF | I4: Automatic
A5: EXT REFS | B5: 0 | E5: Recommended Version | F5: 5.0.0 | H5: Input Value NF | I5: <NF>
A6: Def. Form | E6: Last Modified By Version | F6: 8.3.3 | H6: Input Prob NF | I6: Automatic
A7: Calc Macro | F7: 3364F8AB
A8: Highest# | B8: 24
A10: Anchor Cell | B10: Branch Name | C10: bformtype | D10: valformula | E10: pbformula | F10: distribution | G10: cumPayoffFunction | H10: link | I10: ENDNODEFORMULA | J10: VAL | K10: PB | L10: GenInfo | M10: IntRefs | N10: RefRefs | O10: NodeNames | P10: Collapsed
A11: =Model!$C$35 -> 2900 | B11: =B1 -> Bidding Decision | C11: 0 | I11: DEFAULT | J11: =Model!$B$35 -> 0 | K11: =Model!$B$34 -> 0 | L11: 2,0,0,2,2,3,0,0,0 | M11: 0 | O11: =Model!$C$34 -> Place a bid | P11: FALSE
A12: =Model!$D$13 -> 2900 | B12: Yes | C12: 0 | I12: DEFAULT | J12: =Model!$C$13 -> -7500 | L12: 2,0,0,3,4,5,6,1,0,0 | M12: 0 | O12: =Model!$D$12 -> Bid Amount | P12: FALSE
A13: =Model!$D$37 -> 0 | B13: No | C13: 0 | H13: DEFAULT | I13: DEFAULT | J13: =Model!$C$37 -> 0 | L13: 4,0,0,0,1,0,0 | M13: 0 | P13: FALSE
A14: =Model!$E$9 -> 900 | B14: 160000 | C14: 0 | I14: DEFAULT | J14: =Model!$D$9 -> 0 | L14: 1,0,0,2,7,8,2,0,0 | M14: 0 | O14: =Model!$E$8 -> Any competing bid | P14: FALSE
A15: =Model!$E$21 -> 2900 | B15: 170000 | C15: 0 | I15: DEFAULT | J15: =Model!$D$21 -> 0 | L15: 1,0,0,2,13,18,2,0,0 | M15: 0 | O15: =Model!$E$20 -> Any competing bid | P15: FALSE
A16: =Model!$E$31 -> 900 | B16: 180000 | C16: 0 | I16: DEFAULT | J16: =Model!$D$31 -> 0 | L16: 1,0,0,2,19,24,2,0,0 | M16: 0 | O16: =Model!$E$30 -> Any competing bid | P16: FALSE
A17: =Model!$F$5 -> 500 | B17: Yes | C17: 0 | I17: DEFAULT | J17: =Model!$E$5 -> 0 | K17: =Model!$E$4 -> 0.8 | L17: 1,0,0,2,9,10,4,0,0 | M17: 0 | O17: =Model!$F$4 -> Underbid Competitor | P17: FALSE
A18: =Model!$F$11 -> 2500 | B18: No | C18: 0 | H18: DEFAULT | I18: DEFAULT | J18: =Model!$E$11 -> 10000 | K18: =Model!$E$10 -> 0.2 | L18: 4,0,0,0,4,0,0 | M18: 0 | P18: FALSE
A19: =Model!$G$3 -> 2500 | B19: Yes | C19: 0 | H19: DEFAULT | I19: DEFAULT | J19: =Model!$F$3 -> 10000 | K19: =Model!$F$2 -> 0.8 | L19: 4,0,0,0,7,0,0 | M19: 0 | P19: FALSE
A20: =Model!$G$7 -> -7500 | B20: No | C20: 0 | H20: DEFAULT | I20: DEFAULT | J20: =Model!$F$7 -> 0 | K20: =Model!$F$6 -> 0.2 | L20: 4,0,0,0,7,0,0 | M20: 0 | P20: FALSE
A21: =Model!$G$15 -> 12500 | B21: Yes | C21: 0 | H21: DEFAULT | I21: DEFAULT | J21: =Model!$F$15 -> 20000 | K21: =Model!$F$14 -> 0.4 | L21: 4,0,0,0,13,0,0 | M21: 0 | P21: FALSE
A22: =Model!$G$19 -> -7500 | B22: No | C22: 0 | H22: DEFAULT | I22: DEFAULT | J22: =Model!$F$19 -> 0 | K22: =Model!$F$18 -> 0.6 | L22: 4,0,0,0,13,0,0 | M22: 0 | P22: FALSE
A23: =Model!$F$17 -> 500 | B23: Yes | C23: 0 | I23: DEFAULT | J23: =Model!$E$17 -> 0 | K23: =Model!$E$16 -> 0.8 | L23: 1,0,0,2,11,12,5,0,0 | M23: 0 | O23: =Model!$F$16 -> Underbid Competitor | P23: FALSE
A24: =Model!$G$25 -> 22500 | B24: Yes | C24: 0 | H24: DEFAULT | I24: DEFAULT | J24: =Model!$F$25 -> 30000 | K24: =Model!$F$24 -> 0.1 | L24: 4,0,0,0,19,0,0 | M24: 0 | P24: FALSE
A25: =Model!$G$29 -> -7500 | B25: No | C25: 0 | H25: DEFAULT | I25: DEFAULT | J25: =Model!$F$29 -> 0 | K25: =Model!$F$28 -> 0.9 | L25: 4,0,0,0,19,0,0 | M25: 0 | P25: FALSE
A28: =Model!$F$23 -> 12500 | B28: No | C28: 0 | H28: DEFAULT | I28: DEFAULT | J28: =Model!$E$23 -> 20000 | K28: =Model!$E$22 -> 0.2 | L28: 4,0,0,0,5,0,0 | M28: 0 | P28: FALSE
A29: =Model!$F$27 -> -4500 | B29: Yes | C29: 0 | I29: DEFAULT | J29: =Model!$E$27 -> 0 | K29: =Model!$E$26 -> 0.8 | L29: 1,0,0,2,14,15,6,0,0 | M29: 0 | O29: =Model!$F$26 -> Underbid Competitor | P29: FALSE
A34: =Model!$F$33 -> 22500 | B34: No | C34: 0 | H34: DEFAULT | I34: DEFAULT | J34: =Model!$E$33 -> 30000 | K34: =Model!$E$32 -> 0.2 | L34: 4,0,0,0,6,0,0 | M34: 0 | P34: FALSE

Sheet Building the model
A1: Decision Tree Example
A4: Inputs to the model:
A5: Cost of placing a bid | F5: 7500
A6: Cost of completing the project | F6: 150000
A7: Probability of any competing bids | F7: 0.75
A9: Probability distribution of low competing bids (if any) | I9: Assuming at least one competing bid
A10: Value | F10: Proability | I10: Our bid | L10: Pobability of winning
A11: Less than $160,000 | F11: 0.2 | I11: 160000 | L11: 0.8
A12: Between $160000 and $170000 | F12: 0.4 | I12: 170000 | L12: 0.4
A13: Between $170000 and $180000 | F13: 0.3 | I13: 180000 | L13: 0.1
A14: Greater than $180000 | F14: 0.1
E18: 0.8 | F18: =_xll.PTreeNodeProbability(treeCalc_2!$F$2,9) -> 0
E19: =160000-$F$6 -> 10000 | F19: =_xll.PTreeNodeValue(treeCalc_2!$F$2,9) -> 2500
D20: =$F$7 -> 0.75 | E20: Outbidding Comps
D21: 0 | E21: =_xll.PTreeNodeValue(treeCalc_2!$F$2,7) -> 500
E22: 0.2 | F22: =_xll.PTreeNodeProbability(treeCalc_2!$F$2,10) -> 0
E23: 0 | F23: =_xll.PTreeNodeValue(treeCalc_2!$F$2,10) -> -7500
C24: =_xll.PTreeNodeDecision(treeCalc_2!$F$2,4) -> FALSE | D24: Cometing Bid
C25: 0 | D25: =_xll.PTreeNodeValue(treeCalc_2!$F$2,4) -> 1000
D26: =1-$F$7 -> 0.25 | E26: =_xll.PTreeNodeProbability(treeCalc_2!$F$2,8) -> 0
D27: =160000-$F$6 -> 10000 | E27: =_xll.PTreeNodeValue(treeCalc_2!$F$2,8) -> 2500
B28: =_xll.PTreeNodeDecision(treeCalc_2!$F$2,2) -> TRUE | C28: Amount of Bid
B29: =-$F$5 -> -7500 | C29: =_xll.PTreeNodeValue(treeCalc_2!$F$2,2) -> 3500
E30: 0.4 | F30: =_xll.PTreeNodeProbability(treeCalc_2!$F$2,12) -> 0.3
E31: =170000-$F$6 -> 20000 | F31: =_xll.PTreeNodeValue(treeCalc_2!$F$2,12) -> 12500
D32: =F7 -> 0.75 | E32: Outbidding Comps
D33: 0 | E33: =_xll.PTreeNodeValue(treeCalc_2!$F$2,11) -> 500
E34: 0.6 | F34: =_xll.PTreeNodeProbability(treeCalc_2!$F$2,13) -> 0.45
E35: 0 | F35: =_xll.PTreeNodeValue(treeCalc_2!$F$2,13) -> -7500
C36: =_xll.PTreeNodeDecision(treeCalc_2!$F$2,5) -> TRUE | D36: Cometing Bid
C37: 0 | D37: =_xll.PTreeNodeValue(treeCalc_2!$F$2,5) -> 3500
D38: =1-$F$7 -> 0.25 | E38: =_xll.PTreeNodeProbability(treeCalc_2!$F$2,14) -> 0.25
D39: =170000-$F$6 -> 20000 | E39: =_xll.PTreeNodeValue(treeCalc_2!$F$2,14) -> 12500
E40: 0.1 | F40: =_xll.PTreeNodeProbability(treeCalc_2!$F$2,16) -> 0
E41: =180000-$F$6 -> 30000 | F41: =_xll.PTreeNodeValue(treeCalc_2!$F$2,16) -> 22500
D42: =$F$7 -> 0.75 | E42: Outbidding Comps
D43: 0 | E43: =_xll.PTreeNodeValue(treeCalc_2!$F$2,15) -> -4500
E44: 0.9 | F44: =_xll.PTreeNodeProbability(treeCalc_2!$F$2,17) -> 0
E45: 0 | F45: =_xll.PTreeNodeValue(treeCalc_2!$F$2,17) -> -7500
C46: =_xll.PTreeNodeDecision(treeCalc_2!$F$2,6) -> FALSE | D46: Cometing Bid
...

Sheet ClassDemo
A1: Decision Tree Example
A4: Inputs to the model:
A5: Cost of placing a bid | F5: 7500
A6: Cost of completing the project | F6: 150000
A7: Probability of any competing bids | F7: 0.75
A9: Probability distribution of low competing bids (if any) | I9: Assuming at least one competing bid
A10: Value | F10: Proability | I10: Our bid | L10: Pobability of winning
A11: Less than $160,000 | F11: 0.2 | I11: 160000 | L11: 0.8
A12: Between $160000 and $170000 | F12: 0.4 | I12: 170000 | L12: 0.4
A13: Between $170000 and $180000 | F13: 0.3 | I13: 180000 | L13: 0.1
A14: Greater than $180000 | F14: 0.1

Sheet treeCalc_2
A1: Name | B1: Bidding Decision Model | E1: Ptree1 Compatibility | F1: 3 | H1: Output Label | K1: R-Value Ref. | L1: 100
A2: SheetRef | B2: ='Building the model'!#REF! -> #REF! | E2: Eval. Function | F2: =_xll.PTreeEvaluate5(B3,$L$11:$L$28,$J$11:$J$28,$K$11:$K$28,$N$11:$N$28,$G$11:$G$28,,L1) -> 3884930
A3: GenInfo | B3: 0,2,1,0,0,Exponential, 0,0,-1,0,-1,-1,.0001 | E3: Creation Version | F3: 7.0.1 | H3: Output Value NF | I3: <NF>
A4: Def. Link | B4: = | E4: Required Version | F4: 5.0.0 | H4: Output Prob NF | I4: Automatic
A5: EXT REFS | B5: 0 | E5: Recommended Version | F5: 5.0.0 | H5: Input Value NF | I5: <NF>
A6: Def. Form | E6: Last Modified By Version | F6: 8.3.3 | H6: Input Prob NF | I6: Automatic
A7: Calc Macro | E7: Model GUID | F7: 234DBB4B
A8: Highest# | B8: 18
A10: Anchor Cell | B10: Branch Name | C10: bformtype | D10: valformula | E10: pbformula | F10: distribution | G10: cumPayoffFunction | H10: link | I10: ENDNODEFORMULA | J10: VAL | K10: PB | L10: GenInfo | M10: IntRefs | N10: RefRefs | O10: NodeNames | P10: Collapsed
A11: ='Building the model'!$B$51 -> 3500 | B11: =B1 -> Bidding Decision Model | C11: 0 | I11: DEFAULT | J11: ='Building the model'!$A$51 -> 0 | K11: ='Building the model'!$A$50 -> 0 | L11: 2,0,0,2,2,3,0,0,0 | M11: 0 | O11: ='Building the model'!$B$50 -> Bid | P11: FALSE
A12: ='Building the model'!$C$29 -> 3500 | B12: Yes | C12: 0 | I12: DEFAULT | J12: ='Building the model'!$B$29 -> -7500 | L12: 2,0,0,3,4,5,6,1,0,0 | M12: 0 | O12: ='Building the model'!$C$28 -> Amount of Bid | P12: FALSE
A13: ='Building the model'!$C$53 -> 0 | B13: No | C13: 0 | H13: DEFAULT | I13: DEFAULT | J13: ='Building the model'!$B$53 -> 0 | L13: 4,0,0,0,1,0,0 | M13: 0 | P13: FALSE
A14: ='Building the model'!$D$25 -> 1000 | B14: 160K | C14: 0 | I14: DEFAULT | J14: ='Building the model'!$C$25 -> 0 | L14: 1,0,0,2,7,8,2,0,0 | M14: 0 | O14: ='Building the model'!$D$24 -> Cometing Bid | P14: FALSE
A15: ='Building the model'!$D$37 -> 3500 | B15: 170K | C15: 0 | I15: DEFAULT | J15: ='Building the model'!$C$37 -> 0 | L15: 1,0,0,2,11,14,2,0,0 | M15: 0 | O15: ='Building the model'!$D$36 -> Cometing Bid | P15: FALSE
A16: ='Building the model'!$D$47 -> 2250 | B16: 180K | C16: 0 | I16: DEFAULT | J16: ='Building the model'!$C$47 -> 0 | L16: 1,0,0,2,15,18,2,0,0 | M16: 0 | O16: ='Building the model'!$D$46 -> Cometing Bid | P16: FALSE
A17: ='Building the model'!$E$21 -> 500 | B17: Yes | C17: 0 | I17: DEFAULT | J17: ='Building the model'!$D$21 -> 0 | K17: ='Building the model'!$D$20 -> 0.75 | L17: 1,0,0,2,9,10,4,0,0 | M17: 0 | O17: ='Building the model'!$E$20 -> Outbidding Comps | P17: FALSE
A18: ='Building the model'!$E$27 -> 2500 | B18: No | C18: 0 | H18: DEFAULT | I18: DEFAULT | J18: ='Building the model'!$D$27 -> 10000 | K18: ='Building the model'!$D$26 -> 0.25 | L18: 4,0,0,0,4,0,0 | M18: 0 | P18: FALSE
A19: ='Building the model'!$F$19 -> 2500 | B19: Yes | C19: 0 | H19: DEFAULT | I19: DEFAULT | J19: ='Building the model'!$E$19 -> 10000 | K19: ='Building the model'!$E$18 -> 0.8 | L19: 4,0,0,0,7,0,0 | M19: 0 | P19: FALSE
A20: ='Building the model'!$F$23 -> -7500 | B20: No | C20: 0 | H20: DEFAULT | I20: DEFAULT | J20: ='Building the model'!$E$23 -> 0 | K20: ='Building the model'!$E$22 -> 0.2 | L20: 4,0,0,0,7,0,0 | M20: 0 | P20: FALSE
A21: ='Building the model'!$E$33 -> 500 | B21: Yes | C21: 0 | I21: DEFAULT | J21: ='Building the model'!$D$33 -> 0 | K21: ='Building the model'!$D$32 -> 0.75 | L21: 1,0,0,2,12,13,5,0,0 | M21: 0 | O21: ='Building the model'!$E$32 -> Outbidding Comps | P21: FALSE
A22: ='Building the model'!$F$31 -> 12500 | B22: Yes | C22: 0 | H22: DEFAULT | I22: DEFAULT | J22: ='Building the model'!$E$31 -> 20000 | K22: ='Building the model'!$E$30 -> 0.4 | L22: 4,0,0,0,11,0,0 | M22: 0 | P22: FALSE
A23: ='Building the model'!$F$35 -> -7500 | B23: No | C23: 0 | H23: DEFAULT | I23: DEFAULT | J23: ='Building the model'!$E$35 -> 0 | K23: ='Building the model'!$E$34 -> 0.6 | L23: 4,0,0,0,11,0,0 | M23: 0 | P23: FALSE
A24: ='Building the model'!$E$39 -> 12500 | B24: No | C24: 0 | H24: DEFAULT | I24: DEFAULT | J24: ='Building the model'!$D$39 -> 20000 | K24: ='Building the model'!$D$38 -> 0.25 | L24: 4,0,0,0,5,0,0 | M24: 0 | P24: FALSE
A25: ='Building the model'!$E$43 -> -4500 | B25: Yes | C25: 0 | I25: DEFAULT | J25: ='Building the model'!$D$43 -> 0 | K25: ='Building the model'!$D$42 -> 0.75 | L25: 1,0,0,2,16,17,6,0,0 | M25: 0 | O25: ='Building the model'!$E$42 -> Outbidding Comps | P25: FALSE
A26: ='Building the model'!$F$41 -> 22500 | B26: Yes | C26: 0 | H26: DEFAULT | I26: DEFAULT | J26: ='Building the model'!$E$41 -> 30000 | K26: ='Building the model'!$E$40 -> 0.1 | L26: 4,0,0,0,15,0,0 | M26: 0 | P26: FALSE
A27: ='Building the model'!$F$45 -> -7500 | B27: No | C27: 0 | H27: DEFAULT | I27: DEFAULT | J27: ='Building the model'!$E$45 -> 0 | K27: ='Building the model'!$E$44 -> 0.9 | L27: 4,0,0,0,15,0,0 | M27: 0 | P27: FALSE
A28: ='Building the model'!$E$49 -> 22500 | B28: No | C28: 0 | H28: DEFAULT | I28: DEFAULT | J28: ='Building the model'!$D$49 -> 30000 | K28: ='Building the model'!$D$48 -> 0.25 | L28: 4,0,0,0,6,0,0 | M28: 0 | P28: FALSE
